{"name": "test_demo", "status": "passed", "description": "当用例没有通过时，需要额外处理，日志处理\n    测试用例不通过，抛出异常,才是用例执行失败", "attachments": [{"name": "stdout", "source": "c1e42b57-bab6-4857-82a7-3f82be5e7341-attachment.txt", "type": "text/plain"}], "start": 1610243761064, "stop": 1610243761065, "uuid": "eade0a02-0141-4f9c-a671-8b7c1dce815d", "historyId": "be86bdf88c104431d240b2a182d86acd", "testCaseId": "dcca80bd894cd9e93f55ec05ddf79b00", "fullName": "test_demo#test_demo", "labels": [{"name": "suite", "value": "test_demo"}, {"name": "host", "value": "DESKTOP-15NEG78"}, {"name": "thread", "value": "38032-MainThread"}, {"name": "framework", "value": "pytest"}, {"name": "language", "value": "cpython3"}, {"name": "package", "value": "test_demo"}]}