{"name": "test_demo", "status": "passed", "description": "当用例没有通过时，需要额外处理，日志处理\n    测试用例不通过，抛出异常,才是用例执行失败", "attachments": [{"name": "stdout", "source": "260f382d-18db-4ea1-920b-f102a7cfe0f2-attachment.txt", "type": "text/plain"}], "start": 1610204427595, "stop": 1610204427595, "uuid": "8fa1ff9a-2d5b-4c21-82bf-3cbeac887a16", "historyId": "be86bdf88c104431d240b2a182d86acd", "testCaseId": "dcca80bd894cd9e93f55ec05ddf79b00", "fullName": "test_demo#test_demo", "labels": [{"name": "suite", "value": "test_demo"}, {"name": "host", "value": "DESKTOP-15NEG78"}, {"name": "thread", "value": "33056-MainThread"}, {"name": "framework", "value": "pytest"}, {"name": "language", "value": "cpython3"}, {"name": "package", "value": "test_demo"}]}